Workbook

Sheet COMMANDE
A1: 1000002180 | C1: =IFERROR(VLOOKUP($A:$A,'[1]Liste clients clef'!$A:$B,2,FALSE),"") -> MUDRY, KATELYN | G1: =IFERROR(VLOOKUP($A$1,'[1]Liste clients clef'!$A:$BD,48,FALSE),"") -> 1 | J1: =IFERROR(VLOOKUP($A$1,'[1]Liste clients clef'!$A:$AQ,15,FALSE),"") -> CLEF | K1: SENT ORDER TO: | P1: ORDRE
A2: CODE | B2: 1 | C2: DESCRIPTION | D2: CODE UPC | E2: FORMAT | F2: FORMAT SOLD | G2: $ UNIT | H2: =SUM(H3:H500) -> 450.65 | J2: CS DISCOUNT | K2: =IF(J1="QCON","commandes@quebeccontact.ca",IF(J1="NAT","nlevesque@clefdeschamps.net",IF(J1="LIN","lbrosseau@clefdeschamps.net",IF(J1="DROC","orders@clefdeschamps.net","client@clefdeschamps.net")))) -> client@clefdeschamps.net | M2: 1-A | P2: 1
A3: 220-50 | C3: =IFERROR(VLOOKUP($A:$A,[2]liste!$A:$ZZ,24,FALSE),"") -> BRONCHIX organic | D3: =VLOOKUP(A:A,[2]liste!$A:$AG,33,FALSE) -> 697026182201 | E3: =VLOOKUP($A:$A,[3]SPECS!$A:$AW,22,FALSE) -> 50 ML | F3: =VLOOKUP(A:A,[3]SPECS!$A:$AF,27,FALSE) -> UNIT | G3: =IFERROR(VLOOKUP(A3,'[4]AVA20'!$A:$ZZ,(MATCH($G$1,'[4]AVA20'!$2:$2,0)),FALSE),0) -> 15.25 | H3: =B3*G3*(1-(J3+K3)) -> 0 | J3: =IF(LEFT(M3,3)="4-T",0,IF(LEFT(M3,3)="3-P",0,IF(LEFT(M3,3)="7-T",0,IF(B3=6,0.075,IF(B3=12,0.075,IF(B3=18,0.075,IF(B3=24,0.075,0))))))) -> 0 | M3: =IFERROR(VLOOKUP($A:$A,[2]liste!$A:$Z,5,FALSE),"") -> 1-SUPPLEMENT | N3: =IFERROR(VLOOKUP($A:$A,[2]liste!$A:$Z,6,FALSE),"") -> 1-TEINT MX | P3: =IFERROR(VLOOKUP($A:$A,[5]RÉSUMÉ!$A:$E,5,FALSE),"") -> 3063
A4: 221-50 | C4: =IFERROR(VLOOKUP($A:$A,[2]liste!$A:$ZZ,24,FALSE),"") -> CALMIX organic | D4: =VLOOKUP(A:A,[2]liste!$A:$AG,33,FALSE) -> 697026182218 | E4: =VLOOKUP($A:$A,[3]SPECS!$A:$AW,22,FALSE) -> 50 ML | F4: =VLOOKUP(A:A,[3]SPECS!$A:$AF,27,FALSE) -> UNIT | G4: =IFERROR(VLOOKUP(A4,'[4]AVA20'!$A:$ZZ,(MATCH($G$1,'[4]AVA20'!$2:$2,0)),FALSE),0) -> 15.25 | H4: =B4*G4*(1-(J4+K4)) -> 0 | J4: =IF(LEFT(M4,3)="4-T",0,IF(LEFT(M4,3)="3-P",0,IF(LEFT(M4,3)="7-T",0,IF(B4=6,0.075,IF(B4=12,0.075,IF(B4=18,0.075,IF(B4=24,0.075,0))))))) -> 0 | M4: =IFERROR(VLOOKUP($A:$A,[2]liste!$A:$Z,5,FALSE),"") -> 1-SUPPLEMENT | N4: =IFERROR(VLOOKUP($A:$A,[2]liste!$A:$Z,6,FALSE),"") -> 1-TEINT MX | P4: =IFERROR(VLOOKUP($A:$A,[5]RÉSUMÉ!$A:$E,5,FALSE),"") -> 3064
A5: 232-50 | C5: =IFERROR(VLOOKUP($A:$A,[2]liste!$A:$ZZ,24,FALSE),"") -> DEPURATIX organic | D5: =VLOOKUP(A:A,[2]liste!$A:$AG,33,FALSE) -> 697026182324 | E5: =VLOOKUP($A:$A,[3]SPECS!$A:$AW,22,FALSE) -> 50 ML | F5: =VLOOKUP(A:A,[3]SPECS!$A:$AF,27,FALSE) -> UNIT | G5: =IFERROR(VLOOKUP(A5,'[4]AVA20'!$A:$ZZ,(MATCH($G$1,'[4]AVA20'!$2:$2,0)),FALSE),0) -> 15.25 | H5: =B5*G5*(1-(J5+K5)) -> 0 | J5: =IF(LEFT(M5,3)="4-T",0,IF(LEFT(M5,3)="3-P",0,IF(LEFT(M5,3)="7-T",0,IF(B5=6,0.075,IF(B5=12,0.075,IF(B5=18,0.075,IF(B5=24,0.075,0))))))) -> 0 | M5: =IFERROR(VLOOKUP($A:$A,[2]liste!$A:$Z,5,FALSE),"") -> 1-SUPPLEMENT | N5: =IFERROR(VLOOKUP($A:$A,[2]liste!$A:$Z,6,FALSE),"") -> 1-TEINT MX | P5: =IFERROR(VLOOKUP($A:$A,[5]RÉSUMÉ!$A:$E,5,FALSE),"") -> 3065
A6: 234-50 | C6: =IFERROR(VLOOKUP($A:$A,[2]liste!$A:$ZZ,24,FALSE),"") -> DRASTIX organic | D6: =VLOOKUP(A:A,[2]liste!$A:$AG,33,FALSE) -> 697026192347 | E6: =VLOOKUP($A:$A,[3]SPECS!$A:$AW,22,FALSE) -> 50 ML | F6: =VLOOKUP(A:A,[3]SPECS!$A:$AF,27,FALSE) -> UNIT | G6: =IFERROR(VLOOKUP(A6,'[4]AVA20'!$A:$ZZ,(MATCH($G$1,'[4]AVA20'!$2:$2,0)),FALSE),0) -> 16.5 | H6: =B6*G6*(1-(J6+K6)) -> 0 | J6: =IF(LEFT(M6,3)="4-T",0,IF(LEFT(M6,3)="3-P",0,IF(LEFT(M6,3)="7-T",0,IF(B6=6,0.075,IF(B6=12,0.075,IF(B6=18,0.075,IF(B6=24,0.075,0))))))) -> 0 | M6: =IFERROR(VLOOKUP($A:$A,[2]liste!$A:$Z,5,FALSE),"") -> 1-SUPPLEMENT | N6: =IFERROR(VLOOKUP($A:$A,[2]liste!$A:$Z,6,FALSE),"") -> 1-TEINT MX | P6: =IFERROR(VLOOKUP($A:$A,[5]RÉSUMÉ!$A:$E,5,FALSE),"") -> 3066
A7: 223-50 | C7: =IFERROR(VLOOKUP($A:$A,[2]liste!$A:$ZZ,24,FALSE),"") -> ESTOMIX organic | D7: =VLOOKUP(A:A,[2]liste!$A:$AG,33,FALSE) -> 697026182232 | E7: =VLOOKUP($A:$A,[3]SPECS!$A:$AW,22,FALSE) -> 50 ML | F7: =VLOOKUP(A:A,[3]SPECS!$A:$AF,27,FALSE) -> UNIT | G7: =IFERROR(VLOOKUP(A7,'[4]AVA20'!$A:$ZZ,(MATCH($G$1,'[4]AVA20'!$2:$2,0)),FALSE),0) -> 15.25 | H7: =B7*G7*(1-(J7+K7)) -> 0 | J7: =IF(LEFT(M7,3)="4-T",0,IF(LEFT(M7,3)="3-P",0,IF(LEFT(M7,3)="7-T",0,IF(B7=6,0.075,IF(B7=12,0.075,IF(B7=18,0.075,IF(B7=24,0.075,0))))))) -> 0 | M7: =IFERROR(VLOOKUP($A:$A,[2]liste!$A:$Z,5,FALSE),"") -> 1-SUPPLEMENT | N7: =IFERROR(VLOOKUP($A:$A,[2]liste!$A:$Z,6,FALSE),"") -> 1-TEINT MX | P7: =IFERROR(VLOOKUP($A:$A,[5]RÉSUMÉ!$A:$E,5,FALSE),"") -> 3067
A8: 233-50 | C8: =IFERROR(VLOOKUP($A:$A,[2]liste!$A:$ZZ,24,FALSE),"") -> GINGIVIX organic | D8: =VLOOKUP(A:A,[2]liste!$A:$AG,33,FALSE) -> 697026182331 | E8: =VLOOKUP($A:$A,[3]SPECS!$A:$AW,22,FALSE) -> 50 ML | F8: =VLOOKUP(A:A,[3]SPECS!$A:$AF,27,FALSE) -> UNIT | G8: =IFERROR(VLOOKUP(A8,'[4]AVA20'!$A:$ZZ,(MATCH($G$1,'[4]AVA20'!$2:$2,0)),FALSE),0) -> 15.25 | H8: =B8*G8*(1-(J8+K8)) -> 0 | J8: =IF(LEFT(M8,3)="4-T",0,IF(LEFT(M8,3)="3-P",0,IF(LEFT(M8,3)="7-T",0,IF(B8=6,0.075,IF(B8=12,0.075,IF(B8=18,0.075,IF(B8=24,0.075,0))))))) -> 0 | M8: =IFERROR(VLOOKUP($A:$A,[2]liste!$A:$Z,5,FALSE),"") -> 1-SUPPLEMENT | N8: =IFERROR(VLOOKUP($A:$A,[2]liste!$A:$Z,6,FALSE),"") -> 1-TEINT MX | P8: =IFERROR(VLOOKUP($A:$A,[5]RÉSUMÉ!$A:$E,5,FALSE),"") -> 3068
A9: 224-50 | C9: =IFERROR(VLOOKUP($A:$A,[2]liste!$A:$ZZ,24,FALSE),"") -> HEPATIX organic | D9: =VLOOKUP(A:A,[2]liste!$A:$AG,33,FALSE) -> 697026182249 | E9: =VLOOKUP($A:$A,[3]SPECS!$A:$AW,22,FALSE) -> 50 ML | F9: =VLOOKUP(A:A,[3]SPECS!$A:$AF,27,FALSE) -> UNIT | G9: =IFERROR(VLOOKUP(A9,'[4]AVA20'!$A:$ZZ,(MATCH($G$1,'[4]AVA20'!$2:$2,0)),FALSE),0) -> 15.25 | H9: =B9*G9*(1-(J9+K9)) -> 0 | J9: =IF(LEFT(M9,3)="4-T",0,IF(LEFT(M9,3)="3-P",0,IF(LEFT(M9,3)="7-T",0,IF(B9=6,0.075,IF(B9=12,0.075,IF(B9=18,0.075,IF(B9=24,0.075,0))))))) -> 0 | M9: =IFERROR(VLOOKUP($A:$A,[2]liste!$A:$Z,5,FALSE),"") -> 1-SUPPLEMENT | N9: =IFERROR(VLOOKUP($A:$A,[2]liste!$A:$Z,6,FALSE),"") -> 1-TEINT MX | P9: =IFERROR(VLOOKUP($A:$A,[5]RÉSUMÉ!$A:$E,5,FALSE),"") -> 3069
A10: 225-50 | C10: =IFERROR(VLOOKUP($A:$A,[2]liste!$A:$ZZ,24,FALSE),"") -> HORMONIX organic | D10: =VLOOKUP(A:A,[2]liste!$A:$AG,33,FALSE) -> 697026182256 | E10: =VLOOKUP($A:$A,[3]SPECS!$A:$AW,22,FALSE) -> 50 ML | F10: =VLOOKUP(A:A,[3]SPECS!$A:$AF,27,FALSE) -> UNIT | G10: =IFERROR(VLOOKUP(A10,'[4]AVA20'!$A:$ZZ,(MATCH($G$1,'[4]AVA20'!$2:$2,0)),FALSE),0) -> 15.25 | H10: =B10*G10*(1-(J10+K10)) -> 0 | J10: =IF(LEFT(M10,3)="4-T",0,IF(LEFT(M10,3)="3-P",0,IF(LEFT(M10,3)="7-T",0,IF(B10=6,0.075,IF(B10=12,0.075,IF(B10=18,0.075,IF(B10=24,0.075,0))))))) -> 0 | M10: =IFERROR(VLOOKUP($A:$A,[2]liste!$A:$Z,5,FALSE),"") -> 1-SUPPLEMENT | N10: =IFERROR(VLOOKUP($A:$A,[2]liste!$A:$Z,6,FALSE),"") -> 1-TEINT MX | P10: =IFERROR(VLOOKUP($A:$A,[5]RÉSUMÉ!$A:$E,5,FALSE),"") -> 3070
A11: 226-50 | C11: =IFERROR(VLOOKUP($A:$A,[2]liste!$A:$ZZ,24,FALSE),"") -> INFECTIX organic | D11: =VLOOKUP(A:A,[2]liste!$A:$AG,33,FALSE) -> 697026182263 | E11: =VLOOKUP($A:$A,[3]SPECS!$A:$AW,22,FALSE) -> 50 ML | F11: =VLOOKUP(A:A,[3]SPECS!$A:$AF,27,FALSE) -> UNIT | G11: =IFERROR(VLOOKUP(A11,'[4]AVA20'!$A:$ZZ,(MATCH($G$1,'[4]AVA20'!$2:$2,0)),FALSE),0) -> 15.25 | H11: =B11*G11*(1-(J11+K11)) -> 0 | J11: =IF(LEFT(M11,3)="4-T",0,IF(LEFT(M11,3)="3-P",0,IF(LEFT(M11,3)="7-T",0,IF(B11=6,0.075,IF(B11=12,0.075,IF(B11=18,0.075,IF(B11=24,0.075,0))))))) -> 0 | M11: =IFERROR(VLOOKUP($A:$A,[2]liste!$A:$Z,5,FALSE),"") -> 1-SUPPLEMENT | N11: =IFERROR(VLOOKUP($A:$A,[2]liste!$A:$Z,6,FALSE),"") -> 1-TEINT MX | P11: =IFERROR(VLOOKUP($A:$A,[5]RÉSUMÉ!$A:$E,5,FALSE),"") -> 3071
A12: 231-50 | C12: =IFERROR(VLOOKUP($A:$A,[2]liste!$A:$ZZ,24,FALSE),"") -> MAMABOOST organic | D12: =VLOOKUP(A:A,[2]liste!$A:$AG,33,FALSE) -> 697026182317 | E12: =VLOOKUP($A:$A,[3]SPECS!$A:$AW,22,FALSE) -> 50 ML | F12: =VLOOKUP(A:A,[3]SPECS!$A:$AF,27,FALSE) -> UNIT | G12: =IFERROR(VLOOKUP(A12,'[4]AVA20'!$A:$ZZ,(MATCH($G$1,'[4]AVA20'!$2:$2,0)),FALSE),0) -> 15.25 | H12: =B12*G12*(1-(J12+K12)) -> 0 | J12: =IF(LEFT(M12,3)="4-T",0,IF(LEFT(M12,3)="3-P",0,IF(LEFT(M12,3)="7-T",0,IF(B12=6,0.075,IF(B12=12,0.075,IF(B12=18,0.075,IF(B12=24,0.075,0))))))) -> 0 | M12: =IFERROR(VLOOKUP($A:$A,[2]liste!$A:$Z,5,FALSE),"") -> 1-SUPPLEMENT | N12: =IFERROR(VLOOKUP($A:$A,[2]liste!$A:$Z,6,FALSE),"") -> 1-TEINT MX | P12: =IFERROR(VLOOKUP($A:$A,[5]RÉSUMÉ!$A:$E,5,FALSE),"") -> 3072
A13: 243-50 | C13: =IFERROR(VLOOKUP($A:$A,[2]liste!$A:$ZZ,24,FALSE),"") -> MENOPAUSIX organic | D13: =VLOOKUP(A:A,[2]liste!$A:$AG,33,FALSE) -> 697026182430 | E13: =VLOOKUP($A:$A,[3]SPECS!$A:$AW,22,FALSE) -> 50 ML | F13: =VLOOKUP(A:A,[3]SPECS!$A:$AF,27,FALSE) -> UNIT | G13: =IFERROR(VLOOKUP(A13,'[4]AVA20'!$A:$ZZ,(MATCH($G$1,'[4]AVA20'!$2:$2,0)),FALSE),0) -> 15.25 | H13: =B13*G13*(1-(J13+K13)) -> 0 | J13: =IF(LEFT(M13,3)="4-T",0,IF(LEFT(M13,3)="3-P",0,IF(LEFT(M13,3)="7-T",0,IF(B13=6,0.075,IF(B13=12,0.075,IF(B13=18,0.075,IF(B13=24,0.075,0))))))) -> 0 | M13: =IFERROR(VLOOKUP($A:$A,[2]liste!$A:$Z,5,FALSE),"") -> 1-SUPPLEMENT | N13: =IFERROR(VLOOKUP($A:$A,[2]liste!$A:$Z,6,FALSE),"") -> 1-TEINT MX | P13: =IFERROR(VLOOKUP($A:$A,[5]RÉSUMÉ!$A:$E,5,FALSE),"") -> 3073
A14: 227-50 | C14: =IFERROR(VLOOKUP($A:$A,[2]liste!$A:$ZZ,24,FALSE),"") -> MENSTRUIX organic | D14: =VLOOKUP(A:A,[2]liste!$A:$AG,33,FALSE) -> 697026182270 | E14: =VLOOKUP($A:$A,[3]SPECS!$A:$AW,22,FALSE) -> 50 ML | F14: =VLOOKUP(A:A,[3]SPECS!$A:$AF,27,FALSE) -> UNIT | G14: =IFERROR(VLOOKUP(A14,'[4]AVA20'!$A:$ZZ,(MATCH($G$1,'[4]AVA20'!$2:$2,0)),FALSE),0) -> 15.25 | H14: =B14*G14*(1-(J14+K14)) -> 0 | J14: =IF(LEFT(M14,3)="4-T",0,IF(LEFT(M14,3)="3-P",0,IF(LEFT(M14,3)="7-T",0,IF(B14=6,0.075,IF(B14=12,0.075,IF(B14=18,0.075,IF(B14=24,0.075,0))))))) -> 0 | M14: =IFERROR(VLOOKUP($A:$A,[2]liste!$A:$Z,5,FALSE),"") -> 1-SUPPLEMENT | N14: =IFERROR(VLOOKUP($A:$A,[2]liste!$A:$Z,6,FALSE),"") -> 1-TEINT MX | P14: =IFERROR(VLOOKUP($A:$A,[5]RÉSUMÉ!$A:$E,5,FALSE),"") -> 3074
... A83: 102-50 | C83: =IFERROR(VLOOKUP($A:$A,[2]liste!$A:$ZZ,24,FALSE),"") -> CHASTE TREE Tincture organic | D83: =VLOOKUP(A:A,[2]liste!$A:$AG,33,FALSE) -> 697026131025 | E83: =VLOOKUP($A:$A,[3]SPECS!$A:$AW,22,FALSE) -> 50 ML | F83: =VLOOKUP(A:A,[3]SPECS!$A:$AF,27,FALSE) -> UNIT | G83: =IFERROR(VLOOKUP(A83,'[4]AVA20'!$A:$ZZ,(MATCH($G$1,'[4]AVA20'!$2:$2,0)),FALSE),0) -> 9.75 | H83: =B83*G83*(1-(J83+K83)) -> 0 | J83: =IF(LEFT(M83,3)="4-T",0,IF(LEFT(M83,3)="3-P",0,IF(LEFT(M83,3)="7-T",0,IF(B83=6,0.075,IF(B83=12,0.075,IF(B83=18,0.075,IF(B83=24,0.075,0))))))) -> 0 | M83: =IFERROR(VLOOKUP($A:$A,[2]liste!$A:$Z,5,FALSE),"") -> 1-SUPPLEMENT | N83: =IFERROR(VLOOKUP($A:$A,[2]liste!$A:$Z,6,FALSE),"") -> 1-TEINTURE | P83: =IFERROR(VLOOKUP($A:$A,[5]RÉSUMÉ!$A:$E,5,FALSE),"") -> 3062
A84: 110-100 | C84: =IFERROR(VLOOKUP($A:$A,[2]liste!$A:$ZZ,24,FALSE),"") -> YARROW Tincture organic | D84: =VLOOKUP(A:A,[2]liste!$A:$AG,33,FALSE) -> 697026231107 | E84: =VLOOKUP($A:$A,[3]SPECS!$A:$AW,22,FALSE) -> 100 ML | F84: =VLOOKUP(A:A,[3]SPECS!$A:$AF,27,FALSE) -> UNIT | G84: =VLOOKUP(A:A,'[4]AVA20'!$A:$C,3,FALSE) -> 21.75 | H84: =B84*G84*(1-(J84+K84)) -> 0 | J84: =IF(LEFT(N84,3)="4-T",0,IF(LEFT(N84,3)="3-P",0,IF(LEFT(N84,3)="7-T",0,IF(B84=6,0.075,IF(B84=12,0.075,IF(B84=18,0.075,IF(B84=24,0.075,0))))))) -> 0 | M84: =IFERROR(VLOOKUP($A:$A,[2]liste!$A:$Z,5,FALSE),"") -> 1-SUPPLEMENT | N84: =IFERROR(VLOOKUP($A:$A,[2]liste!$A:$Z,6,FALSE),"") -> 1-TEINTURE | P84: =IFERROR(VLOOKUP($A:$A,[5]RÉSUMÉ!$A:$E,5,FALSE),"") -> 302
A85: 128-100 | C85: =IFERROR(VLOOKUP($A:$A,[2]liste!$A:$ZZ,24,FALSE),"") -> ASHWAGANDHA Tincture organic | D85: =VLOOKUP(A:A,[2]liste!$A:$AG,33,FALSE) -> 697026231282 | E85: =VLOOKUP($A:$A,[3]SPECS!$A:$AW,22,FALSE) -> 100 ML | F85: =VLOOKUP(A:A,[3]SPECS!$A:$AF,27,FALSE) -> UNIT | G85: =VLOOKUP(A:A,'[4]AVA20'!$A:$C,3,FALSE) -> 25.5 | H85: =B85*G85*(1-(J85+K85)) -> 0 | J85: =IF(LEFT(N85,3)="4-T",0,IF(LEFT(N85,3)="3-P",0,IF(LEFT(N85,3)="7-T",0,IF(B85=6,0.075,IF(B85=12,0.075,IF(B85=18,0.075,IF(B85=24,0.075,0))))))) -> 0 | M85: =IFERROR(VLOOKUP($A:$A,[2]liste!$A:$Z,5,FALSE),"") -> 1-SUPPLEMENT | N85: =IFERROR(VLOOKUP($A:$A,[2]liste!$A:$Z,6,FALSE),"") -> 1-TEINTURE | P85: =IFERROR(VLOOKUP($A:$A,[5]RÉSUMÉ!$A:$E,5,FALSE),"") -> 301
A86: 190-100 | C86: =IFERROR(VLOOKUP($A:$A,[2]liste!$A:$ZZ,24,FALSE),"") -> ASTRAGALUS Tincture organic | D86: =VLOOKUP(A:A,[2]liste!$A:$AG,33,FALSE) -> 697026231909 | E86: =VLOOKUP($A:$A,[3]SPECS!$A:$AW,22,FALSE) -> 100 ML | F86: =VLOOKUP(A:A,[3]SPECS!$A:$AF,27,FALSE) -> UNIT | G86: =VLOOKUP(A:A,'[4]AVA20'!$A:$C,3,FALSE) -> 27 | H86: =B86*G86*(1-(J86+K86)) -> 0 | J86: =IF(LEFT(N86,3)="4-T",0,IF(LEFT(N86,3)="3-P",0,IF(LEFT(N86,3)="7-T",0,IF(B86=6,0.075,IF(B86=12,0.075,IF(B86=18,0.075,IF(B86=24,0.075,0))))))) -> 0 | M86: =IFERROR(VLOOKUP($A:$A,[2]liste!$A:$Z,5,FALSE),"") -> 1-SUPPLEMENT | N86: =IFERROR(VLOOKUP($A:$A,[2]liste!$A:$Z,6,FALSE),"") -> 1-TEINTURE | P86: =IFERROR(VLOOKUP($A:$A,[5]RÉSUMÉ!$A:$E,5,FALSE),"") -> 303
A87: 894-100 | C87: =IFERROR(VLOOKUP($A:$A,[2]liste!$A:$ZZ,24,FALSE),"") -> GREEN OATSTRAW Tincture organic | D87: =VLOOKUP(A:A,[2]liste!$A:$AG,33,FALSE) -> 697026238946 | E87: =VLOOKUP($A:$A,[3]SPECS!$A:$AW,22,FALSE) -> 100 ML | F87: =VLOOKUP(A:A,[3]SPECS!$A:$AF,27,FALSE) -> UNIT | G87: =VLOOKUP(A:A,'[4]AVA20'!$A:$C,3,FALSE) -> 20 | H87: =B87*G87*(1-(J87+K87)) -> 0 | J87: =IF(LEFT(N87,3)="4-T",0,IF(LEFT(N87,3)="3-P",0,IF(LEFT(N87,3)="7-T",0,IF(B87=6,0.075,IF(B87=12,0.075,IF(B87=18,0.075,IF(B87=24,0.075,0))))))) -> 0 | M87: =IFERROR(VLOOKUP($A:$A,[2]liste!$A:$Z,5,FALSE),"") -> 1-SUPPLEMENT | N87: =IFERROR(VLOOKUP($A:$A,[2]liste!$A:$Z,6,FALSE),"") -> 1-TEINTURE | P87: =IFERROR(VLOOKUP($A:$A,[5]RÉSUMÉ!$A:$E,5,FALSE),"") -> 304
A88: 174-100 | C88: =IFERROR(VLOOKUP($A:$A,[2]liste!$A:$ZZ,24,FALSE),"") -> BURDOCK Tincture organic | D88: =VLOOKUP(A:A,[2]liste!$A:$AG,33,FALSE) -> 697026231749 | E88: =VLOOKUP($A:$A,[3]SPECS!$A:$AW,22,FALSE) -> 100 ML | F88: =VLOOKUP(A:A,[3]SPECS!$A:$AF,27,FALSE) -> UNIT | G88: =VLOOKUP(A:A,'[4]AVA20'!$A:$C,3,FALSE) -> 23.25 | H88: =B88*G88*(1-(J88+K88)) -> 0 | J88: =IF(LEFT(N88,3)="4-T",0,IF(LEFT(N88,3)="3-P",0,IF(LEFT(N88,3)="7-T",0,IF(B88=6,0.075,IF(B88=12,0.075,IF(B88=18,0.075,IF(B88=24,0.075,0))))))) -> 0 | M88: =IFERROR(VLOOKUP($A:$A,[2]liste!$A:$Z,5,FALSE),"") -> 1-SUPPLEMENT | N88: =IFERROR(VLOOKUP($A:$A,[2]liste!$A:$Z,6,FALSE),"") -> 1-TEINTURE | P88: =IFERROR(VLOOKUP($A:$A,[5]RÉSUMÉ!$A:$E,5,FALSE),"") -> 305
A89: 161-100 | C89: =IFERROR(VLOOKUP($A:$A,[2]liste!$A:$ZZ,24,FALSE),"") -> HOLY BASIL Tincture organic | D89: =VLOOKUP(A:A,[2]liste!$A:$AG,33,FALSE) -> 697026231619 | E89: =VLOOKUP($A:$A,[3]SPECS!$A:$AW,22,FALSE) -> 100 ML | F89: =VLOOKUP(A:A,[3]SPECS!$A:$AF,27,FALSE) -> UNIT | G89: =VLOOKUP(A:A,'[4]AVA20'!$A:$C,3,FALSE) -> 22 | H89: =B89*G89*(1-(J89+K89)) -> 0 | J89: =IF(LEFT(N89,3)="4-T",0,IF(LEFT(N89,3)="3-P",0,IF(LEFT(N89,3)="7-T",0,IF(B89=6,0.075,IF(B89=12,0.075,IF(B89=18,0.075,IF(B89=24,0.075,0))))))) -> 0 | M89: =IFERROR(VLOOKUP($A:$A,[2]liste!$A:$Z,5,FALSE),"") -> 1-SUPPLEMENT | N89: =IFERROR(VLOOKUP($A:$A,[2]liste!$A:$Z,6,FALSE),"") -> 1-TEINTURE | P89: =IFERROR(VLOOKUP($A:$A,[5]RÉSUMÉ!$A:$E,5,FALSE),"") -> 306
A90: 109-100 | C90: =IFERROR(VLOOKUP($A:$A,[2]liste!$A:$ZZ,24,FALSE),"") -> CATNIP Tincture organic | D90: =VLOOKUP(A:A,[2]liste!$A:$AG,33,FALSE) -> 697026231091 | E90: =VLOOKUP($A:$A,[3]SPECS!$A:$AW,22,FALSE) -> 100 ML | F90: =VLOOKUP(A:A,[3]SPECS!$A:$AF,27,FALSE) -> UNIT | G90: =VLOOKUP(A:A,'[4]AVA20'!$A:$C,3,FALSE) -> 23.75 | H90: =B90*G90*(1-(J90+K90)) -> 0 | J90: =IF(LEFT(N90,3)="4-T",0,IF(LEFT(N90,3)="3-P",0,IF(LEFT(N90,3)="7-T",0,IF(B90=6,0.075,IF(B90=12,0.075,IF(B90=18,0.075,IF(B90=24,0.075,0))))))) -> 0 | M90: =IFERROR(VLOOKUP($A:$A,[2]liste!$A:$Z,5,FALSE),"") -> 1-SUPPLEMENT | N90: =IFERROR(VLOOKUP($A:$A,[2]liste!$A:$Z,6,FALSE),"") -> 1-TEINTURE | P90: =IFERROR(VLOOKUP($A:$A,[5]RÉSUMÉ!$A:$E,5,FALSE),"") -> 307
A91: 898-100 | C91: =IFERROR(VLOOKUP($A:$A,[2]liste!$A:$ZZ,24,FALSE),"") -> MILK THISTLE Tincture organic | D91: =VLOOKUP(A:A,[2]liste!$A:$AG,33,FALSE) -> 697026118989 | E91: =VLOOKUP($A:$A,[3]SPECS!$A:$AW,22,FALSE) -> 100 ML | F91: =VLOOKUP(A:A,[3]SPECS!$A:$AF,27,FALSE) -> UNIT | G91: =VLOOKUP(A:A,'[4]AVA20'!$A:$C,3,FALSE) -> 21 | H91: =B91*G91*(1-(J91+K91)) -> 0 | J91: =IF(LEFT(N91,3)="4-T",0,IF(LEFT(N91,3)="3-P",0,IF(LEFT(N91,3)="7-T",0,IF(B91=6,0.075,IF(B91=12,0.075,IF(B91=18,0.075,IF(B91=24,0.075,0))))))) -> 0 | M91: =IFERROR(VLOOKUP($A:$A,[2]liste!$A:$Z,5,FALSE),"") -> 1-SUPPLEMENT | N91: =IFERROR(VLOOKUP($A:$A,[2]liste!$A:$Z,6,FALSE),"") -> 1-TEINTURE | P91: =IFERROR(VLOOKUP($A:$A,[5]RÉSUMÉ!$A:$E,5,FALSE),"") -> 308
A92: 202-100 | C92: =IFERROR(VLOOKUP($A:$A,[2]liste!$A:$ZZ,24,FALSE),"") -> TURMERIC Tincture organic | D92: =VLOOKUP(A:A,[2]liste!$A:$AG,33,FALSE) -> 697026232029 | E92: =VLOOKUP($A:$A,[3]SPECS!$A:$AW,22,FALSE) -> 100 ML | F92: =VLOOKUP(A:A,[3]SPECS!$A:$AF,27,FALSE) -> UNIT | G92: =VLOOKUP(A:A,'[4]AVA20'!$A:$C,3,FALSE) -> 23.5 | H92: =B92*G92*(1-(J92+K92)) -> 0 | J92: =IF(LEFT(N92,3)="4-T",0,IF(LEFT(N92,3)="3-P",0,IF(LEFT(N92,3)="7-T",0,IF(B92=6,0.075,IF(B92=12,0.075,IF(B92=18,0.075,IF(B92=24,0.075,0))))))) -> 0 | M92: =IFERROR(VLOOKUP($A:$A,[2]liste!$A:$Z,5,FALSE),"") -> 1-SUPPLEMENT | N92: =IFERROR(VLOOKUP($A:$A,[2]liste!$A:$Z,6,FALSE),"") -> 1-TEINTURE | P92: =IFERROR(VLOOKUP($A:$A,[5]RÉSUMÉ!$A:$E,5,FALSE),"") -> 309
A93: 117-100 | C93: =IFERROR(VLOOKUP($A:$A,[2]liste!$A:$ZZ,24,FALSE),"") -> ECHINACEA Tincture organic | D93: =VLOOKUP(A:A,[2]liste!$A:$AG,33,FALSE) -> 697026231176 | E93: =VLOOKUP($A:$A,[3]SPECS!$A:$AW,22,FALSE) -> 100 ML | F93: =VLOOKUP(A:A,[3]SPECS!$A:$AF,27,FALSE) -> UNIT | G93: =VLOOKUP(A:A,'[4]AVA20'!$A:$C,3,FALSE) -> 20 | H93: =B93*G93*(1-(J93+K93)) -> 0 | J93: =IF(LEFT(N93,3)="4-T",0,IF(LEFT(N93,3)="3-P",0,IF(LEFT(N93,3)="7-T",0,IF(B93=6,0.075,IF(B93=12,0.075,IF(B93=18,0.075,IF(B93=24,0.075,0))))))) -> 0 | M93: =IFERROR(VLOOKUP($A:$A,[2]liste!$A:$Z,5,FALSE),"") -> 1-SUPPLEMENT | N93: =IFERROR(VLOOKUP($A:$A,[2]liste!$A:$Z,6,FALSE),"") -> 1-TEINTURE | P93: =IFERROR(VLOOKUP($A:$A,[5]RÉSUMÉ!$A:$E,5,FALSE),"") -> 310
A94: 186-100 | C94: =IFERROR(VLOOKUP($A:$A,[2]liste!$A:$ZZ,24,FALSE),"") -> RED RASPBERRY Tincture organic | D94: =VLOOKUP(A:A,[2]liste!$A:$AG,33,FALSE) -> 697026231862 | E94: =VLOOKUP($A:$A,[3]SPECS!$A:$AW,22,FALSE) -> 100 ML | F94: =VLOOKUP(A:A,[3]SPECS!$A:$AF,27,FALSE) -> UNIT | G94: =VLOOKUP(A:A,'[4]AVA20'!$A:$C,3,FALSE) -> 21.75 | H94: =B94*G94*(1-(J94+K94)) -> 0 | J94: =IF(LEFT(N94,3)="4-T",0,IF(LEFT(N94,3)="3-P",0,IF(LEFT(N94,3)="7-T",0,IF(B94=6,0.075,IF(B94=12,0.075,IF(B94=18,0.075,IF(B94=24,0.075,0))))))) -> 0 | M94: =IFERROR(VLOOKUP($A:$A,[2]liste!$A:$Z,5,FALSE),"") -> 1-SUPPLEMENT | N94: =IFERROR(VLOOKUP($A:$A,[2]liste!$A:$Z,6,FALSE),"") -> 1-TEINTURE | P94: =IFERROR(VLOOKUP($A:$A,[5]RÉSUMÉ!$A:$E,5,FALSE),"") -> 311
A95: 114-100 | C95: =IFERROR(VLOOKUP($A:$A,[2]liste!$A:$ZZ,24,FALSE),"") -> GINSENG Tincture organic | D95: =VLOOKUP(A:A,[2]liste!$A:$AG,33,FALSE) -> 697026231145 | E95: =VLOOKUP($A:$A,[3]SPECS!$A:$AW,22,FALSE) -> 100 ML | F95: =VLOOKUP(A:A,[3]SPECS!$A:$AF,27,FALSE) -> UNIT | G95: =VLOOKUP(A:A,'[4]AVA20'!$A:$C,3,FALSE) -> 33 | H95: =B95*G95*(1-(J95+K95)) -> 0 | J95: =IF(LEFT(N95,3)="4-T",0,IF(LEFT(N95,3)="3-P",0,IF(LEFT(N95,3)="7-T",0,IF(B95=6,0.075,IF(B95=12,0.075,IF(B95=18,0.075,IF(B95=24,0.075,0))))))) -> 0 | M95: =IFERROR(VLOOKUP($A:$A,[2]liste!$A:$Z,5,FALSE),"") -> 1-SUPPLEMENT | N95: =IFERROR(VLOOKUP($A:$A,[2]liste!$A:$Z,6,FALSE),"") -> 1-TEINTURE | P95: =IFERROR(VLOOKUP($A:$A,[5]RÉSUMÉ!$A:$E,5,FALSE),"") -> 312
... A111: 102-100 | C111: =IFERROR(VLOOKUP($A:$A,[2]liste!$A:$ZZ,24,FALSE),"") -> CHASTE TREE Tincture organic | D111: =VLOOKUP(A:A,[2]liste!$A:$AG,33,FALSE) -> 697026231022 | E111: =VLOOKUP($A:$A,[3]SPECS!$A:$AW,22,FALSE) -> 100 ML | F111: =VLOOKUP(A:A,[3]SPECS!$A:$AF,27,FALSE) -> UNIT | G111: =VLOOKUP(A:A,'[4]AVA20'!$A:$C,3,FALSE) -> 18.75 | H111: =B111*G111*(1-(J111+K111)) -> 0 | J111: =IF(LEFT(N111,3)="4-T",0,IF(LEFT(N111,3)="3-P",0,IF(LEFT(N111,3)="7-T",0,IF(B111=6,0.075,IF(B111=12,0.075,IF(B111=18,0.075,IF(B111=24,0.075,0))))))) -> 0 | M111: =IFERROR(VLOOKUP($A:$A,[2]liste!$A:$Z,5,FALSE),"") -> 1-SUPPLEMENT | N111: =IFERROR(VLOOKUP($A:$A,[2]liste!$A:$Z,6,FALSE),"") -> 1-TEINTURE | P111: =IFERROR(VLOOKUP($A:$A,[5]RÉSUMÉ!$A:$E,5,FALSE),"") -> 328
A112: 746-60 | C112: =IFERROR(VLOOKUP($A:$A,[2]liste!$A:$ZZ,24,FALSE),"") -> KIDS Syrup organic | D112: =VLOOKUP(A:A,[2]liste!$A:$AG,33,FALSE) -> 697026247467 | E112: =VLOOKUP($A:$A,[3]SPECS!$A:$AW,22,FALSE) -> 60 ML | F112: =VLOOKUP(A:A,[3]SPECS!$A:$AF,27,FALSE) -> UNIT | G112: =IFERROR(VLOOKUP(A112,'[4]AVA20'!$A:$ZZ,(MATCH($G$1,'[4]AVA20'!$2:$2,0)),FALSE),0) -> 15.25 | H112: =B112*G112*(1-(J112+K112)) -> 0 | J112: =IF(LEFT(M112,3)="4-T",0,IF(LEFT(M112,3)="3-P",0,IF(LEFT(M112,3)="7-T",0,IF(B112=6,0.075,IF(B112=12,0.075,IF(B112=18,0.075,IF(B112=24,0.075,0))))))) -> 0 | M112: =IFERROR(VLOOKUP($A:$A,[2]liste!$A:$Z,5,FALSE),"") -> 1-SUPPLEMENT | N112: =IFERROR(VLOOKUP($A:$A,[2]liste!$A:$Z,6,FALSE),"") -> 3-SIROP | P112: =IFERROR(VLOOKUP($A:$A,[5]RÉSUMÉ!$A:$E,5,FALSE),"") -> 3079
A113: 745-60 | C113: =IFERROR(VLOOKUP($A:$A,[2]liste!$A:$ZZ,24,FALSE),"") -> COUGH Syrup organic | D113: =VLOOKUP(A:A,[2]liste!$A:$AG,33,FALSE) -> 697026247450 | E113: =VLOOKUP($A:$A,[3]SPECS!$A:$AW,22,FALSE) -> 60 ML | F113: =VLOOKUP(A:A,[3]SPECS!$A:$AF,27,FALSE) -> UNIT | G113: =IFERROR(VLOOKUP(A113,'[4]AVA20'!$A:$ZZ,(MATCH($G$1,'[4]AVA20'!$2:$2,0)),FALSE),0) -> 15.25 | H113: =B113*G113*(1-(J113+K113)) -> 0 | J113: =IF(LEFT(M113,3)="4-T",0,IF(LEFT(M113,3)="3-P",0,IF(LEFT(M113,3)="7-T",0,IF(B113=6,0.075,IF(B113=12,0.075,IF(B113=18,0.075,IF(B113=24,0.075,0))))))) -> 0 | M113: =IFERROR(VLOOKUP($A:$A,[2]liste!$A:$Z,5,FALSE),"") -> 1-SUPPLEMENT | N113: =IFERROR(VLOOKUP($A:$A,[2]liste!$A:$Z,6,FALSE),"") -> 3-SIROP | P113: =IFERROR(VLOOKUP($A:$A,[5]RÉSUMÉ!$A:$E,5,FALSE),"") -> 3079
A114: 713-60 | C114: =IFERROR(VLOOKUP($A:$A,[2]liste!$A:$ZZ,24,FALSE),"") -> ECHINACEA PROPOLIS organic | D114: =VLOOKUP(A:A,[2]liste!$A:$AG,33,FALSE) -> 697026247139 | E114: =VLOOKUP($A:$A,[3]SPECS!$A:$AW,22,FALSE) -> 60 ML | F114: =VLOOKUP(A:A,[3]SPECS!$A:$AF,27,FALSE) -> UNIT | G114: =IFERROR(VLOOKUP(A114,'[4]AVA20'!$A:$ZZ,(MATCH($G$1,'[4]AVA20'!$2:$2,0)),FALSE),0) -> 15.25 | H114: =B114*G114*(1-(J114+K114)) -> 0 | J114: =IF(LEFT(M114,3)="4-T",0,IF(LEFT(M114,3)="3-P",0,IF(LEFT(M114,3)="7-T",0,IF(B114=6,0.075,IF(B114=12,0.075,IF(B114=18,0.075,IF(B114=24,0.075,0))))))) -> 0 | M114: =IFERROR(VLOOKUP($A:$A,[2]liste!$A:$Z,5,FALSE),"") -> 1-SUPPLEMENT | N114: =IFERROR(VLOOKUP($A:$A,[2]liste!$A:$Z,6,FALSE),"") -> 3-SIROP | P114: =IFERROR(VLOOKUP($A:$A,[5]RÉSUMÉ!$A:$E,5,FALSE),"") -> 3116
A115: 619-15 | C115: =IFERROR(VLOOKUP($A:$A,[2]liste!$A:$ZZ,24,FALSE),"") -> ARNICA Salve organic | D115: =VLOOKUP(A:A,[2]liste!$A:$AG,33,FALSE) -> 697026586191 | E115: =VLOOKUP($A:$A,[3]SPECS!$A:$AW,22,FALSE) -> 15 ML | F115: =VLOOKUP(A:A,[3]SPECS!$A:$AF,27,FALSE) -> UNIT | G115: =IFERROR(VLOOKUP(A115,'[4]AVA20'!$A:$ZZ,(MATCH($G$1,'[4]AVA20'!$2:$2,0)),FALSE),0) -> 6.55 | H115: =B115*G115*(1-(J115+K115)) -> 0 | J115: =IF(LEFT(M115,3)="4-T",0,IF(LEFT(M115,3)="3-P",0,IF(LEFT(M115,3)="7-T",0,IF(B115=6,0.075,IF(B115=12,0.075,IF(B115=18,0.075,IF(B115=24,0.075,0))))))) -> 0 | M115: =IFERROR(VLOOKUP($A:$A,[2]liste!$A:$Z,5,FALSE),"") -> z-disc | N115: =IFERROR(VLOOKUP($A:$A,[2]liste!$A:$Z,6,FALSE),"") -> z-disc | P115: =IFERROR(VLOOKUP($A:$A,[5]RÉSUMÉ!$A:$E,5,FALSE),"") -> 3109
A116: 619-50 | C116: =IFERROR(VLOOKUP($A:$A,[2]liste!$A:$ZZ,24,FALSE),"") -> ARNICA Salve organic | D116: =VLOOKUP(A:A,[2]liste!$A:$AG,33,FALSE) -> 697026516198 | E116: =VLOOKUP($A:$A,[3]SPECS!$A:$AW,22,FALSE) -> 50 ML | F116: =VLOOKUP(A:A,[3]SPECS!$A:$AF,27,FALSE) -> UNIT | G116: =IFERROR(VLOOKUP(A116,'[4]AVA20'!$A:$ZZ,(MATCH($G$1,'[4]AVA20'!$2:$2,0)),FALSE),0) -> 12.95 | H116: =B116*G116*(1-(J116+K116)) -> 0 | J116: =IF(LEFT(M116,3)="4-T",0,IF(LEFT(M116,3)="3-P",0,IF(LEFT(M116,3)="7-T",0,IF(B116=6,0.075,IF(B116=12,0.075,IF(B116=18,0.075,IF(B116=24,0.075,0))))))) -> 0 | M116: =IFERROR(VLOOKUP($A:$A,[2]liste!$A:$Z,5,FALSE),"") -> z-disc | N116: =IFERROR(VLOOKUP($A:$A,[2]liste!$A:$Z,6,FALSE),"") -> z-disc | P116: =IFERROR(VLOOKUP($A:$A,[5]RÉSUMÉ!$A:$E,5,FALSE),"") -> 3115
A117: 611-15 | C117: =IFERROR(VLOOKUP($A:$A,[2]liste!$A:$ZZ,24,FALSE),"") -> BIOBABY Salve organic | D117: =VLOOKUP(A:A,[2]liste!$A:$AG,33,FALSE) -> 697026586115 | E117: =VLOOKUP($A:$A,[3]SPECS!$A:$AW,22,FALSE) -> 15 ML | F117: =VLOOKUP(A:A,[3]SPECS!$A:$AF,27,FALSE) -> UNIT | G117: =IFERROR(VLOOKUP(A117,'[4]AVA20'!$A:$ZZ,(MATCH($G$1,'[4]AVA20'!$2:$2,0)),FALSE),0) -> 6.55 | H117: =B117*G117*(1-(J117+K117)) -> 0 | J117: =IF(LEFT(M117,3)="4-T",0,IF(LEFT(M117,3)="3-P",0,IF(LEFT(M117,3)="7-T",0,IF(B117=6,0.075,IF(B117=12,0.075,IF(B117=18,0.075,IF(B117=24,0.075,0))))))) -> 0 | M117: =IFERROR(VLOOKUP($A:$A,[2]liste!$A:$Z,5,FALSE),"") -> 1-SUPPLEMENT | N117: =IFERROR(VLOOKUP($A:$A,[2]liste!$A:$Z,6,FALSE),"") -> 5-ONGUENT | P117: =IFERROR(VLOOKUP($A:$A,[5]RÉSUMÉ!$A:$E,5,FALSE),"") -> 3110
A118: 611-50 | C118: =IFERROR(VLOOKUP($A:$A,[2]liste!$A:$ZZ,24,FALSE),"") -> BIOBABY Salve organic | D118: =VLOOKUP(A:A,[2]liste!$A:$AG,33,FALSE) -> 697026516112 | E118: =VLOOKUP($A:$A,[3]SPECS!$A:$AW,22,FALSE) -> 50 ML | F118: =VLOOKUP(A:A,[3]SPECS!$A:$AF,27,FALSE) -> UNIT | G118: =IFERROR(VLOOKUP(A118,'[4]AVA20'!$A:$ZZ,(MATCH($G$1,'[4]AVA20'!$2:$2,0)),FALSE),0) -> 12.95 | H118: =B118*G118*(1-(J118+K118)) -> 0 | J118: =IF(LEFT(M118,3)="4-T",0,IF(LEFT(M118,3)="3-P",0,IF(LEFT(M118,3)="7-T",0,IF(B118=6,0.075,IF(B118=12,0.075,IF(B118=18,0.075,IF(B118=24,0.075,0))))))) -> 0 | M118: =IFERROR(VLOOKUP($A:$A,[2]liste!$A:$Z,5,FALSE),"") -> 1-SUPPLEMENT | N118: =IFERROR(VLOOKUP($A:$A,[2]liste!$A:$Z,6,FALSE),"") -> 5-ONGUENT | P118: =IFERROR(VLOOKUP($A:$A,[5]RÉSUMÉ!$A:$E,5,FALSE),"") -> 3116
A119: 612-15 | C119: =IFERROR(VLOOKUP($A:$A,[2]liste!$A:$ZZ,24,FALSE),"") -> CALENDULA Salve organic | D119: =VLOOKUP(A:A,[2]liste!$A:$AG,33,FALSE) -> 697026586122 | E119: =VLOOKUP($A:$A,[3]SPECS!$A:$AW,22,FALSE) -> 15 ML | F119: =VLOOKUP(A:A,[3]SPECS!$A:$AF,27,FALSE) -> UNIT | G119: =IFERROR(VLOOKUP(A119,'[4]AVA20'!$A:$ZZ,(MATCH($G$1,'[4]AVA20'!$2:$2,0)),FALSE),0) -> 6.55 | H119: =B119*G119*(1-(J119+K119)) -> 0 | J119: =IF(LEFT(M119,3)="4-T",0,IF(LEFT(M119,3)="3-P",0,IF(LEFT(M119,3)="7-T",0,IF(B119=6,0.075,IF(B119=12,0.075,IF(B119=18,0.075,IF(B119=24,0.075,0))))))) -> 0 | M119: =IFERROR(VLOOKUP($A:$A,[2]liste!$A:$Z,5,FALSE),"") -> 1-SUPPLEMENT | N119: =IFERROR(VLOOKUP($A:$A,[2]liste!$A:$Z,6,FALSE),"") -> 5-ONGUENT | P119: =IFERROR(VLOOKUP($A:$A,[5]RÉSUMÉ!$A:$E,5,FALSE),"") -> 3111
A120: 612-50 | C120: =IFERROR(VLOOKUP($A:$A,[2]liste!$A:$ZZ,24,FALSE),"") -> CALENDULA Salve organic | D120: =VLOOKUP(A:A,[2]liste!$A:$AG,33,FALSE) -> 697026516129 | E120: =VLOOKUP($A:$A,[3]SPECS!$A:$AW,22,FALSE) -> 50 ML | F120: =VLOOKUP(A:A,[3]SPECS!$A:$AF,27,FALSE) -> UNIT | G120: =IFERROR(VLOOKUP(A120,'[4]AVA20'!$A:$ZZ,(MATCH($G$1,'[4]AVA20'!$2:$2,0)),FALSE),0) -> 12.95 | H120: =B120*G120*(1-(J120+K120)) -> 0 | J120: =IF(LEFT(M120,3)="4-T",0,IF(LEFT(M120,3)="3-P",0,IF(LEFT(M120,3)="7-T",0,IF(B120=6,0.075,IF(B120=12,0.075,IF(B120=18,0.075,IF(B120=24,0.075,0))))))) -> 0 | M120: =IFERROR(VLOOKUP($A:$A,[2]liste!$A:$Z,5,FALSE),"") -> 1-SUPPLEMENT | N120: =IFERROR(VLOOKUP($A:$A,[2]liste!$A:$Z,6,FALSE),"") -> 5-ONGUENT | P120: =IFERROR(VLOOKUP($A:$A,[5]RÉSUMÉ!$A:$E,5,FALSE),"") -> 3117
A121: 613-15 | C121: =IFERROR(VLOOKUP($A:$A,[2]liste!$A:$ZZ,24,FALSE),"") -> COMFREY Salve organic | D121: =VLOOKUP(A:A,[2]liste!$A:$AG,33,FALSE) -> 697026586139 | E121: =VLOOKUP($A:$A,[3]SPECS!$A:$AW,22,FALSE) -> 15 ML | F121: =VLOOKUP(A:A,[3]SPECS!$A:$AF,27,FALSE) -> UNIT | G121: =IFERROR(VLOOKUP(A121,'[4]AVA20'!$A:$ZZ,(MATCH($G$1,'[4]AVA20'!$2:$2,0)),FALSE),0) -> 6.55 | H121: =B121*G121*(1-(J121+K121)) -> 0 | J121: =IF(LEFT(M121,3)="4-T",0,IF(LEFT(M121,3)="3-P",0,IF(LEFT(M121,3)="7-T",0,IF(B121=6,0.075,IF(B121=12,0.075,IF(B121=18,0.075,IF(B121=24,0.075,0))))))) -> 0 | M121: =IFERROR(VLOOKUP($A:$A,[2]liste!$A:$Z,5,FALSE),"") -> 1-SUPPLEMENT | N121: =IFERROR(VLOOKUP($A:$A,[2]liste!$A:$Z,6,FALSE),"") -> 5-ONGUENT | P121: =IFERROR(VLOOKUP($A:$A,[5]RÉSUMÉ!$A:$E,5,FALSE),"") -> 3112
A122: 613-50 | C122: =IFERROR(VLOOKUP($A:$A,[2]liste!$A:$ZZ,24,FALSE),"") -> COMFREY Salve organic | D122: =VLOOKUP(A:A,[2]liste!$A:$AG,33,FALSE) -> 697026516136 | E122: =VLOOKUP($A:$A,[3]SPECS!$A:$AW,22,FALSE) -> 50 ML | F122: =VLOOKUP(A:A,[3]SPECS!$A:$AF,27,FALSE) -> UNIT | G122: =IFERROR(VLOOKUP(A122,'[4]AVA20'!$A:$ZZ,(MATCH($G$1,'[4]AVA20'!$2:$2,0)),FALSE),0) -> 12.95 | H122: =B122*G122*(1-(J122+K122)) -> 0 | J122: =IF(LEFT(M122,3)="4-T",0,IF(LEFT(M122,3)="3-P",0,IF(LEFT(M122,3)="7-T",0,IF(B122=6,0.075,IF(B122=12,0.075,IF(B122=18,0.075,IF(B122=24,0.075,0))))))) -> 0 | M122: =IFERROR(VLOOKUP($A:$A,[2]liste!$A:$Z,5,FALSE),"") -> 1-SUPPLEMENT | N122: =IFERROR(VLOOKUP($A:$A,[2]liste!$A:$Z,6,FALSE),"") -> 5-ONGUENT | P122: =IFERROR(VLOOKUP($A:$A,[5]RÉSUMÉ!$A:$E,5,FALSE),"") -> 3118
A123: 614-15 | C123: =IFERROR(VLOOKUP($A:$A,[2]liste!$A:$ZZ,24,FALSE),"") -> HERBAL Salve organic | D123: =VLOOKUP(A:A,[2]liste!$A:$AG,33,FALSE) -> 697026586146 | E123: =VLOOKUP($A:$A,[3]SPECS!$A:$AW,22,FALSE) -> 15 ML | F123: =VLOOKUP(A:A,[3]SPECS!$A:$AF,27,FALSE) -> UNIT | G123: =IFERROR(VLOOKUP(A123,'[4]AVA20'!$A:$ZZ,(MATCH($G$1,'[4]AVA20'!$2:$2,0)),FALSE),0) -> 6.55 | H123: =B123*G123*(1-(J123+K123)) -> 0 | J123: =IF(LEFT(M123,3)="4-T",0,IF(LEFT(M123,3)="3-P",0,IF(LEFT(M123,3)="7-T",0,IF(B123=6,0.075,IF(B123=12,0.075,IF(B123=18,0.075,IF(B123=24,0.075,0))))))) -> 0 | M123: =IFERROR(VLOOKUP($A:$A,[2]liste!$A:$Z,5,FALSE),"") -> 1-SUPPLEMENT | N123: =IFERROR(VLOOKUP($A:$A,[2]liste!$A:$Z,6,FALSE),"") -> 5-ONGUENT | P123: =IFERROR(VLOOKUP($A:$A,[5]RÉSUMÉ!$A:$E,5,FALSE),"") -> 3113
...

Sheet Feuil2
A3: 6
A4: 12
A5: 18
A6: 24
A7: 30
A8: 36
A9: 42
A10: 48
A11: 54
A12: 60
A13: 66
A14: 72

Sheet Feuil1
